Workbook
Name _Hlk183085033: 'BASE & OPTION'!$B$7
Name _Hlk183096932: 'BASE & OPTION'!$B$1

Sheet Instructions
A1: INSTRUCTIONS
A2: CLIN 0001 is a firm-fixed price CLIN that is grouped by Sprint Teams. These CLINs will be firm fixed price based on the Contractor's proposed number of Iterations (or "Sprints") required of various Teams to support the period of performance. CLIN 0002 is a not-to-exceed (NTE) T&M CLIN based on a proposed ceiling of an on-call team required to ensure 24x7 product support after go live to Production. CLIN 0003-0004 is cost reimbursable CLIN that will fund apporved travel and Other Direct Costs. CLIN 0005 is a not-to-exceed (NTE) CLIN made up of associated, firm-fixed-unit-price (FFUP) "step-CLINs" (0005a, 0005b, 0005c, 0005d) to establish a cost basis for the Government to approve additional Teams as Sprint objectives demand. CLIN 0001 will be funded at the time of award. CLIN 0002 - 0005 will be funded as needed at the discretion of the Government. Step-CLINs will establish a price per Team per Sprint. For this CAMP pricing template, the number of optional teams have been pre-filled in each step-CLIN tab. The awarded Contractor will not activate Teams under any CLIN without prior approval from the COR. The awarded Contractor will invoice the government per Sprint. Should the combined value of exercised T&M, cost reimbursable, or NTE CLIN achieve 75% of its stated value, the Contractor will notify the COR and request direction on the continued use of funds so as not to exceed the total available funds.
A3: On the LCATs & Rates worksheet, the offeror is asked to provide labor categories (LCATs) and rates applicable to the current year of its GSA MAS. Please also provide an escalation rate for labor rates. Please modify the escalation rate as applicable and additional discounts to labor rates are strongly encouraged.
A4: On the Project Manager, Product Design, Engineering, DevOps, On-Call Support, and Optional Teams worksheets, the offeror is asked to select the GSA MAS LCATs most relevant to roles found on a typical Agile team. Crosswalking LCATs to roles found on the Agile team(s) is allowed; please indicate the crosswalked role in the designated column. The Government will evaluate whether the selected LCAT meets its expectations for seniority and expertise for the role(s) indicated. Please provide estimated hrs. required from each LCAT/role for each Iteration to develop the Firm Fixed Price per Iteration for each Period of Performance. Anticipated Other Direct Costs (ODC), including travel needs, should also be documented. $50,000 for for Travel may be used for estimation purposes for this cost reimbursable CLINs. Sheets may be duplicated or combined for the offeror to propose the CLIN structure that offers the most effective blend of flexibility and predictably for successful contract performance.

Sheet LCATs & Rates
A1: Escalation Rate: | B1: 0.02
B3: GSA MAS Rates | F3: Discounted Rates
A4: Labor Category (LCAT) | B4: Base Period | C4: Option Period 1 | D4: Option Period 2 | E4: Discount Offered, if any | F4: Base Period | G4: Option Period 1 | H4: Option Period 2
A5: Product /Program Manager | B5: 168 | C5: =B5*(1+$B$1) -> 171.36 | D5: =C5*(1+$B$1) -> 174.7872 | E5: 0 | F5: =B5*(1-$E5) -> 168 | G5: =C5*(1-$E5) -> 171.36 | H5: =D5*(1-$E5) -> 174.7872
A6: Subject Matter Expert | B6: 185 | C6: =B6*(1+$B$1) -> 188.7 | D6: =C6*(1+$B$1) -> 192.474 | E6: 0.09 | F6: =B6*(1-$E6) -> 168.35 | G6: =C6*(1-$E6) -> 171.717 | H6: =D6*(1-$E6) -> 175.15134
A7: Consultant | B7: 185 | C7: =B7*(1+$B$1) -> 188.7 | D7: =C7*(1+$B$1) -> 192.474 | E7: 0 | F7: =B7*(1-$E7) -> 185 | G7: =C7*(1-$E7) -> 188.7 | H7: =D7*(1-$E7) -> 192.474
A8: Developer | B8: 212 | C8: =B8*(1+$B$1) -> 216.24 | D8: =C8*(1+$B$1) -> 220.5648 | E8: 0.12 | F8: =B8*(1-$E8) -> 186.56 | G8: =C8*(1-$E8) -> 190.2912 | H8: =D8*(1-$E8) -> 194.09702
A9: UX/UI Designer | B9: 143 | C9: =B9*(1+$B$1) -> 145.86 | D9: =C9*(1+$B$1) -> 148.7772 | E9: 0 | F9: =B9*(1-$E9) -> 143 | G9: =C9*(1-$E9) -> 145.86 | H9: =D9*(1-$E9) -> 148.7772
A10: IT Content Strategy | B10: 127 | C10: =B10*(1+$B$1) -> 129.54 | D10: =C10*(1+$B$1) -> 132.1308 | E10: 0 | F10: =B10*(1-$E10) -> 127 | G10: =C10*(1-$E10) -> 129.54 | H10: =D10*(1-$E10) -> 132.1308
A11: IT Training | B11: 159 | C11: =B11*(1+$B$1) -> 162.18 | D11: =C11*(1+$B$1) -> 165.4236 | E11: 0.08 | F11: =B11*(1-$E11) -> 146.28 | G11: =C11*(1-$E11) -> 149.2056 | H11: =D11*(1-$E11) -> 152.18971
A12: Digital Transformer | B12: 159 | C12: =B12*(1+$B$1) -> 162.18 | D12: =C12*(1+$B$1) -> 165.4236 | E12: 0 | F12: =B12*(1-$E12) -> 159 | G12: =C12*(1-$E12) -> 162.18 | H12: =D12*(1-$E12) -> 165.4236
B13: 0 | C13: =B13*(1+$B$1) -> 0 | D13: =C13*(1+$B$1) -> 0 | E13: 0 | F13: =B13*(1-$E13) -> 0 | G13: =C13*(1-$E13) -> 0 | H13: =D13*(1-$E13) -> 0
B14: 0 | C14: =B14*(1+$B$1) -> 0 | D14: =C14*(1+$B$1) -> 0 | E14: 0 | F14: =B14*(1-$E14) -> 0 | G14: =C14*(1-$E14) -> 0 | H14: =D14*(1-$E14) -> 0
B15: 0 | C15: =B15*(1+$B$1) -> 0 | D15: =C15*(1+$B$1) -> 0 | E15: 0 | F15: =B15*(1-$E15) -> 0 | G15: =C15*(1-$E15) -> 0 | H15: =D15*(1-$E15) -> 0
B16: 0 | C16: =B16*(1+$B$1) -> 0 | D16: =C16*(1+$B$1) -> 0 | E16: 0 | F16: =B16*(1-$E16) -> 0 | G16: =C16*(1-$E16) -> 0 | H16: =D16*(1-$E16) -> 0
B17: 0 | C17: =B17*(1+$B$1) -> 0 | D17: =C17*(1+$B$1) -> 0 | E17: 0 | F17: =B17*(1-$E17) -> 0 | G17: =C17*(1-$E17) -> 0 | H17: =D17*(1-$E17) -> 0
B18: 0 | C18: =B18*(1+$B$1) -> 0 | D18: =C18*(1+$B$1) -> 0 | E18: 0 | F18: =B18*(1-$E18) -> 0 | G18: =C18*(1-$E18) -> 0 | H18: =D18*(1-$E18) -> 0
B19: 0 | C19: =B19*(1+$B$1) -> 0 | D19: =C19*(1+$B$1) -> 0 | E19: 0 | F19: =B19*(1-$E19) -> 0 | G19: =C19*(1-$E19) -> 0 | H19: =D19*(1-$E19) -> 0
B20: 0 | C20: =B20*(1+$B$1) -> 0 | D20: =C20*(1+$B$1) -> 0 | E20: 0 | F20: =B20*(1-$E20) -> 0 | G20: =C20*(1-$E20) -> 0 | H20: =D20*(1-$E20) -> 0
B21: 0 | C21: =B21*(1+$B$1) -> 0 | D21: =C21*(1+$B$1) -> 0 | E21: 0 | F21: =B21*(1-$E21) -> 0 | G21: =C21*(1-$E21) -> 0 | H21: =D21*(1-$E21) -> 0
B22: 0 | C22: =B22*(1+$B$1) -> 0 | D22: =C22*(1+$B$1) -> 0 | E22: 0 | F22: =B22*(1-$E22) -> 0 | G22: =C22*(1-$E22) -> 0 | H22: =D22*(1-$E22) -> 0
B23: 0 | C23: =B23*(1+$B$1) -> 0 | D23: =C23*(1+$B$1) -> 0 | E23: 0 | F23: =B23*(1-$E23) -> 0 | G23: =C23*(1-$E23) -> 0 | H23: =D23*(1-$E23) -> 0
B24: 0 | C24: =B24*(1+$B$1) -> 0 | D24: =C24*(1+$B$1) -> 0 | E24: 0 | F24: =B24*(1-$E24) -> 0 | G24: =C24*(1-$E24) -> 0 | H24: =D24*(1-$E24) -> 0
... B44: 0 | C44: =B44*(1+$B$1) -> 0 | D44: =C44*(1+$B$1) -> 0 | E44: 0 | F44: =B44*(1-$E44) -> 0 | G44: =C44*(1-$E44) -> 0 | H44: =D44*(1-$E44) -> 0

Sheet BASE & OPTION
B1: BASE YEAR - 12 Months
B2: CLIN | C2: Description | D2: Quantity | E2: Unit | F2: Unit Price | G2: Extended Price
B4: 1 | C4: Project Manager Team (FFPPS) | D4: 1 | E4: Sprint | F4: 0 | G4: =F4*D4 -> 0
C5: Product Design Team (FFPPS) | D5: 1 | E5: Sprint | F5: 0 | G5: =F5*D5 -> 0
C6: Engineering Team (FFP) | D6: 1 | E6: Sprint | F6: 0 | G6: =F6*D6 -> 0
C7: DevOps Team (FFPPS) | D7: 1 | E7: Sprint | F7: 0 | G7: =F7*D7 -> 0
B8: 2 | C8: On Call Support Team (T&M) | D8: 1 | E8: Not-to-Exceed | F8: 0 | G8: =F8*D8 -> 0
B9: 3 | C9: Travel | D9: 1 | E9: Lot | F9: 50000 | G9: =F9*D9 -> 50000
B10: 4 | C10: Other Direct Costs | D10: 1 | E10: Lot | F10: 10000 | G10: =F10*D10 -> 10000
B11: 5 | C11: Optional Teams, as needed (NTE) | D11: - | E11: Not-to-Exceed | F11: - | G11: =SUM(G12:G15) -> 0
B12: 0005a | C12: Project Management Team (FFUP) | D12: 52 | E12: Sprint | F12: 0 | G12: =F12*D12 -> 0
B13: 0005b | C13: Product Design Team (FFUP) | D13: 52 | E13: Sprint | F13: 0 | G13: =F13*D13 -> 0
B14: 0005c | C14: Engineering Team (FFUP) | D14: 52 | E14: Sprint | F14: 0 | G14: =F14*D14 -> 0
B15: 0005d | C15: DevOps Team (FFUP) | D15: 52 | E15: Sprint | F15: 0 | G15: =F15*D15 -> 0
C16: Base Year Total | D16: - | E16: - | F16: - | G16: =SUM(G4:G11) -> 60000
B20: OPTION YEAR 1 - 12 Months
B21: CLIN | C21: Description | D21: Quantity | E21: Unit | F21: Unit Price | G21: Extended Price
B23: 1001 | C23: Project Manager Team (FFPPS) | D23: 1 | E23: Sprint | F23: 0 | G23: =F23*D23 -> 0
C24: Product Design Team (FFPPS) | D24: 1 | E24: Sprint | F24: 0 | G24: =F24*D24 -> 0
C25: Engineering Team (FFP) | D25: 1 | E25: Sprint | F25: 0 | G25: =F25*D25 -> 0
C26: DevOps Team (FFPPS) | D26: 1 | E26: Sprint | F26: 0 | G26: =F26*D26 -> 0
B27: 1002 | C27: On Call Support Team (T&M) | D27: 1 | E27: Not-to-Exceed | F27: 0 | G27: =F27*D27 -> 0
B28: 1003 | C28: Travel | D28: 1 | E28: Lot | F28: 50000 | G28: =F28*D28 -> 50000
B29: 1004 | C29: Other Direct Costs | D29: 1 | E29: Lot | F29: 10000 | G29: =F29*D29 -> 10000
B30: 1005 | C30: Optional Teams, as needed (NTE) | D30: - | E30: Not-to-Exceed | F30: - | G30: =SUM(G31:G34) -> 0
B31: 1005a | C31: Project Management Team (FFUP) | D31: 52 | E31: Sprint | F31: 0 | G31: =F31*D31 -> 0
B32: 1005b | C32: Product Design Team (FFUP) | D32: 52 | E32: Sprint | F32: 0 | G32: =F32*D32 -> 0
B33: 1005c | C33: Engineering Team (FFUP) | D33: 52 | E33: Sprint | F33: 0 | G33: =F33*D33 -> 0
B34: 1005d | C34: DevOps Team (FFUP) | D34: 52 | E34: Sprint | F34: 0 | G34: =F34*D34 -> 0
C35: OY1 Total | D35: - | E35: - | F35: - | G35: =SUM(G23:G30) -> 60000
B38: OPTION YEAR 2 - 12 Months
B39: CLIN | C39: Description | D39: Quantity | E39: Unit | F39: Unit Price | G39: Extended Price
B41: 2001 | C41: Project Manager Team (FFPPS) | D41: 1 | E41: Sprint | F41: 0 | G41: =F41*D41 -> 0
C42: Product Design Team (FFPPS) | D42: 1 | E42: Sprint | F42: 0 | G42: =F42*D42 -> 0
C43: Engineering Team (FFP) | D43: 1 | E43: Sprint | F43: 0 | G43: =F43*D43 -> 0
C44: DevOps Team (FFPPS) | D44: 1 | E44: Sprint | F44: 0 | G44: =F44*D44 -> 0
B45: 2002 | C45: On Call Support Team (T&M) | D45: 1 | E45: Not-to-Exceed | F45: 0 | G45: =F45*D45 -> 0
B46: 2003 | C46: Travel | D46: 1 | E46: Lot | F46: 50000 | G46: =F46*D46 -> 50000
B47: 2004 | C47: Other Direct Costs | D47: 1 | E47: Lot | F47: 10000 | G47: =F47*D47 -> 10000
B48: 2005 | C48: Optional Teams, as needed (NTE) | D48: - | E48: Not-to-Exceed | F48: - | G48: =SUM(G49:G52) -> 0
...

Sheet BASE & OPTION_Project Manager
A1: Labor - BASE PERIOD
A2: Labor Category (Select from List) | B2: Crosswalked Role (Manual entry, if applicable) | C2: Rate per Hour (Calculated) | D2: Hrs per Iteration (Manual Entry) | E2: Base Period Price per Iteration (Calculated)
A3: Product /Program Manager | B3: Delivery Manager | C3: =_xlfn.XLOOKUP(A3,'LCATs & Rates'!$A$5:$A$44,'LCATs & Rates'!$F$5:$F$44) -> 168 | D3: 74 | E3: =$C3*$D3 -> 12432
C4: =_xlfn.XLOOKUP(A4,'LCATs & Rates'!$A$5:$A$44,'LCATs & Rates'!$F$5:$F$44) -> 0 | E4: =$C4*$D4 -> 0
C5: =_xlfn.XLOOKUP(A5,'LCATs & Rates'!$A$5:$A$44,'LCATs & Rates'!$F$5:$F$44) -> 0 | E5: =$C5*$D5 -> 0
C6: =_xlfn.XLOOKUP(A6,'LCATs & Rates'!$A$5:$A$44,'LCATs & Rates'!$F$5:$F$44) -> 0 | E6: =$C6*$D6 -> 0
C7: =_xlfn.XLOOKUP(A7,'LCATs & Rates'!$A$5:$A$44,'LCATs & Rates'!$F$5:$F$44) -> 0 | E7: =$C7*$D7 -> 0
C8: =_xlfn.XLOOKUP(A8,'LCATs & Rates'!$A$5:$A$44,'LCATs & Rates'!$F$5:$F$44) -> 0 | E8: =$C8*$D8 -> 0
C9: =_xlfn.XLOOKUP(A9,'LCATs & Rates'!$A$5:$A$44,'LCATs & Rates'!$F$5:$F$44) -> 0 | E9: =$C9*$D9 -> 0
C10: =_xlfn.XLOOKUP(A10,'LCATs & Rates'!$A$5:$A$44,'LCATs & Rates'!$F$5:$F$44) -> 0 | E10: =$C10*$D10 -> 0
C11: =_xlfn.XLOOKUP(A11,'LCATs & Rates'!$A$5:$A$44,'LCATs & Rates'!$F$5:$F$44) -> 0 | E11: =$C11*$D11 -> 0
C12: =_xlfn.XLOOKUP(A12,'LCATs & Rates'!$A$5:$A$44,'LCATs & Rates'!$F$5:$F$44) -> 0 | E12: =$C12*$D12 -> 0
C13: =_xlfn.XLOOKUP(A13,'LCATs & Rates'!$A$5:$A$44,'LCATs & Rates'!$F$5:$F$44) -> 0 | E13: =$C13*$D13 -> 0
C14: =_xlfn.XLOOKUP(A14,'LCATs & Rates'!$A$5:$A$44,'LCATs & Rates'!$F$5:$F$44) -> 0 | E14: =$C14*$D14 -> 0
A15: Price per Team per Iteration | E15: =SUM(E3:E14) -> 12432
A16: # of Teams Proposed | E16: 1
A17: # of Sprints Proposed | E17: 26
A18: Base Period Subtotal | E18: =E15*E16*E17 -> 323232
A20: Other Direct Costs (ODC) / Travel
A21: Item Description | B21: Item Category | C21: Qty | D21: Unit | E21: Cost per Unit | F21: Extended Cost
A22: TBD | B22: Travel | C22: 1 | D22: Lot | E22: 50000 | F22: =E22*C22 -> 50000
A23: TBD | B23: ODC | C23: 1 | D23: Lot | E23: 10000 | F23: =E23*C23 -> 10000
E24: ODC/Travel Total | F24: =SUM(F22:F23) -> 60000
A27: Labor - OPTION PERIOD 1
A28: Labor Category (Select from List) | B28: Crosswalked Role (Manual entry, if applicable) | C28: Rate per Hour (Calculated) | D28: Hrs per Iteration (Manual Entry) | E28: Option Period
A29: Product /Program Manager | C29: =_xlfn.XLOOKUP(A29,'LCATs & Rates'!$A$5:$A$44,'LCATs & Rates'!$G$5:$G$44) -> 171.36 | D29: 74 | E29: =$C29*$D29 -> 12680.64
C30: =_xlfn.XLOOKUP(A30,'LCATs & Rates'!$A$5:$A$44,'LCATs & Rates'!$G$5:$G$44) -> 0 | E30: =$C30*$D30 -> 0
C31: =_xlfn.XLOOKUP(A31,'LCATs & Rates'!$A$5:$A$44,'LCATs & Rates'!$G$5:$G$44) -> 0 | E31: =$C31*$D31 -> 0
C32: =_xlfn.XLOOKUP(A32,'LCATs & Rates'!$A$5:$A$44,'LCATs & Rates'!$G$5:$G$44) -> 0 | E32: =$C32*$D32 -> 0
C33: =_xlfn.XLOOKUP(A33,'LCATs & Rates'!$A$5:$A$44,'LCATs & Rates'!$G$5:$G$44) -> 0 | E33: =$C33*$D33 -> 0
C34: =_xlfn.XLOOKUP(A34,'LCATs & Rates'!$A$5:$A$44,'LCATs & Rates'!$G$5:$G$44) -> 0 | E34: =$C34*$D34 -> 0
C35: =_xlfn.XLOOKUP(A35,'LCATs & Rates'!$A$5:$A$44,'LCATs & Rates'!$G$5:$G$44) -> 0 | E35: =$C35*$D35 -> 0
C36: =_xlfn.XLOOKUP(A36,'LCATs & Rates'!$A$5:$A$44,'LCATs & Rates'!$G$5:$G$44) -> 0 | E36: =$C36*$D36 -> 0
C37: =_xlfn.XLOOKUP(A37,'LCATs & Rates'!$A$5:$A$44,'LCATs & Rates'!$G$5:$G$44) -> 0 | E37: =$C37*$D37 -> 0
C38: =_xlfn.XLOOKUP(A38,'LCATs & Rates'!$A$5:$A$44,'LCATs & Rates'!$G$5:$G$44) -> 0 | E38: =$C38*$D38 -> 0
C39: =_xlfn.XLOOKUP(A39,'LCATs & Rates'!$A$5:$A$44,'LCATs & Rates'!$G$5:$G$44) -> 0 | E39: =$C39*$D39 -> 0
C40: =_xlfn.XLOOKUP(A40,'LCATs & Rates'!$A$5:$A$44,'LCATs & Rates'!$G$5:$G$44) -> 0 | E40: =$C40*$D40 -> 0
A41: Price per Team per Iteration | E41: =SUM(E29:E40) -> 12680.64
A42: # of Teams Proposed | E42: 1
A43: # of Sprints Proposed | E43: 26
...

Sheet BASE & OPTION_Product Design
A1: Labor - BASE PERIOD
A2: Labor Category (Select from List) | B2: Crosswalked Role (Manual entry, if applicable) | C2: Rate per Hour (Calculated) | D2: Hrs per Iteration (Manual Entry) | E2: Base Period Price per Iteration (Calculated)
A3: Product /Program Manager | C3: =_xlfn.XLOOKUP(A3,'LCATs & Rates'!$A$5:$A$44,'LCATs & Rates'!$F$5:$F$44) -> 168 | D3: 74 | E3: =$C3*$D3 -> 12432
A4: Subject Matter Expert | C4: =_xlfn.XLOOKUP(A4,'LCATs & Rates'!$A$5:$A$44,'LCATs & Rates'!$F$5:$F$44) -> 168.35 | D4: 74 | E4: =$C4*$D4 -> 12457.9
C5: =_xlfn.XLOOKUP(A5,'LCATs & Rates'!$A$5:$A$44,'LCATs & Rates'!$F$5:$F$44) -> 0 | E5: =$C5*$D5 -> 0
C6: =_xlfn.XLOOKUP(A6,'LCATs & Rates'!$A$5:$A$44,'LCATs & Rates'!$F$5:$F$44) -> 0 | E6: =$C6*$D6 -> 0
C7: =_xlfn.XLOOKUP(A7,'LCATs & Rates'!$A$5:$A$44,'LCATs & Rates'!$F$5:$F$44) -> 0 | E7: =$C7*$D7 -> 0
C8: =_xlfn.XLOOKUP(A8,'LCATs & Rates'!$A$5:$A$44,'LCATs & Rates'!$F$5:$F$44) -> 0 | E8: =$C8*$D8 -> 0
C9: =_xlfn.XLOOKUP(A9,'LCATs & Rates'!$A$5:$A$44,'LCATs & Rates'!$F$5:$F$44) -> 0 | E9: =$C9*$D9 -> 0
C10: =_xlfn.XLOOKUP(A10,'LCATs & Rates'!$A$5:$A$44,'LCATs & Rates'!$F$5:$F$44) -> 0 | E10: =$C10*$D10 -> 0
C11: =_xlfn.XLOOKUP(A11,'LCATs & Rates'!$A$5:$A$44,'LCATs & Rates'!$F$5:$F$44) -> 0 | E11: =$C11*$D11 -> 0
C12: =_xlfn.XLOOKUP(A12,'LCATs & Rates'!$A$5:$A$44,'LCATs & Rates'!$F$5:$F$44) -> 0 | E12: =$C12*$D12 -> 0
C13: =_xlfn.XLOOKUP(A13,'LCATs & Rates'!$A$5:$A$44,'LCATs & Rates'!$F$5:$F$44) -> 0 | E13: =$C13*$D13 -> 0
C14: =_xlfn.XLOOKUP(A14,'LCATs & Rates'!$A$5:$A$44,'LCATs & Rates'!$F$5:$F$44) -> 0 | E14: =$C14*$D14 -> 0
A15: Price per Team per Iteration | E15: =SUM(E3:E14) -> 24889.9
A16: # of Teams Proposed | E16: 1
A17: # of Sprints Proposed | E17: 26
A18: Base Period Subtotal | E18: =E15*E16*E17 -> 647137.4
A20: Other Direct Costs (ODC) / Travel
A21: Item Description | B21: Item Category | C21: Qty | D21: Unit | E21: Cost per Unit | F21: Extended Cost
A22: TBD | B22: Travel | C22: 1 | D22: Lot | E22: 0 | F22: =E22*C22 -> 0
A23: TBD | B23: ODC | C23: 1 | D23: Lot | E23: 0 | F23: =E23*C23 -> 0
E24: ODC/Travel Total | F24: =SUM(F22:F23) -> 0
A27: Labor - OPTION PERIOD 1
A28: Labor Category (Select from List) | B28: Crosswalked Role (Manual entry, if applicable) | C28: Rate per Hour (Calculated) | D28: Hrs per Iteration (Manual Entry) | E28: Option Period
C29: =_xlfn.XLOOKUP(A29,'LCATs & Rates'!$A$5:$A$44,'LCATs & Rates'!$G$5:$G$44) -> 0 | E29: =$C29*$D29 -> 0
C30: =_xlfn.XLOOKUP(A30,'LCATs & Rates'!$A$5:$A$44,'LCATs & Rates'!$G$5:$G$44) -> 0 | E30: =$C30*$D30 -> 0
C31: =_xlfn.XLOOKUP(A31,'LCATs & Rates'!$A$5:$A$44,'LCATs & Rates'!$G$5:$G$44) -> 0 | E31: =$C31*$D31 -> 0
C32: =_xlfn.XLOOKUP(A32,'LCATs & Rates'!$A$5:$A$44,'LCATs & Rates'!$G$5:$G$44) -> 0 | E32: =$C32*$D32 -> 0
C33: =_xlfn.XLOOKUP(A33,'LCATs & Rates'!$A$5:$A$44,'LCATs & Rates'!$G$5:$G$44) -> 0 | E33: =$C33*$D33 -> 0
C34: =_xlfn.XLOOKUP(A34,'LCATs & Rates'!$A$5:$A$44,'LCATs & Rates'!$G$5:$G$44) -> 0 | E34: =$C34*$D34 -> 0
C35: =_xlfn.XLOOKUP(A35,'LCATs & Rates'!$A$5:$A$44,'LCATs & Rates'!$G$5:$G$44) -> 0 | E35: =$C35*$D35 -> 0
C36: =_xlfn.XLOOKUP(A36,'LCATs & Rates'!$A$5:$A$44,'LCATs & Rates'!$G$5:$G$44) -> 0 | E36: =$C36*$D36 -> 0
C37: =_xlfn.XLOOKUP(A37,'LCATs & Rates'!$A$5:$A$44,'LCATs & Rates'!$G$5:$G$44) -> 0 | E37: =$C37*$D37 -> 0
C38: =_xlfn.XLOOKUP(A38,'LCATs & Rates'!$A$5:$A$44,'LCATs & Rates'!$G$5:$G$44) -> 0 | E38: =$C38*$D38 -> 0
C39: =_xlfn.XLOOKUP(A39,'LCATs & Rates'!$A$5:$A$44,'LCATs & Rates'!$G$5:$G$44) -> 0 | E39: =$C39*$D39 -> 0
C40: =_xlfn.XLOOKUP(A40,'LCATs & Rates'!$A$5:$A$44,'LCATs & Rates'!$G$5:$G$44) -> 0 | E40: =$C40*$D40 -> 0
A41: Price per Team per Iteration | E41: =SUM(E29:E40) -> 0
A42: # of Teams Proposed | E42: 1
A43: # of Sprints Proposed | E43: 26
...

Sheet BASE & OPTION_Engineering
A1: Labor - BASE PERIOD
A2: Labor Category (Select from List) | B2: Crosswalked Role (Manual entry, if applicable) | C2: Rate per Hour (Calculated) | D2: Hrs per Iteration (Manual Entry) | E2: Base Period Price per Iteration (Calculated)
C3: =_xlfn.XLOOKUP(A3,'LCATs & Rates'!$A$5:$A$44,'LCATs & Rates'!$F$5:$F$44) -> 0 | E3: =$C3*$D3 -> 0
C4: =_xlfn.XLOOKUP(A4,'LCATs & Rates'!$A$5:$A$44,'LCATs & Rates'!$F$5:$F$44) -> 0 | E4: =$C4*$D4 -> 0
C5: =_xlfn.XLOOKUP(A5,'LCATs & Rates'!$A$5:$A$44,'LCATs & Rates'!$F$5:$F$44) -> 0 | E5: =$C5*$D5 -> 0
C6: =_xlfn.XLOOKUP(A6,'LCATs & Rates'!$A$5:$A$44,'LCATs & Rates'!$F$5:$F$44) -> 0 | E6: =$C6*$D6 -> 0
C7: =_xlfn.XLOOKUP(A7,'LCATs & Rates'!$A$5:$A$44,'LCATs & Rates'!$F$5:$F$44) -> 0 | E7: =$C7*$D7 -> 0
C8: =_xlfn.XLOOKUP(A8,'LCATs & Rates'!$A$5:$A$44,'LCATs & Rates'!$F$5:$F$44) -> 0 | E8: =$C8*$D8 -> 0
C9: =_xlfn.XLOOKUP(A9,'LCATs & Rates'!$A$5:$A$44,'LCATs & Rates'!$F$5:$F$44) -> 0 | E9: =$C9*$D9 -> 0
C10: =_xlfn.XLOOKUP(A10,'LCATs & Rates'!$A$5:$A$44,'LCATs & Rates'!$F$5:$F$44) -> 0 | E10: =$C10*$D10 -> 0
C11: =_xlfn.XLOOKUP(A11,'LCATs & Rates'!$A$5:$A$44,'LCATs & Rates'!$F$5:$F$44) -> 0 | E11: =$C11*$D11 -> 0
C12: =_xlfn.XLOOKUP(A12,'LCATs & Rates'!$A$5:$A$44,'LCATs & Rates'!$F$5:$F$44) -> 0 | E12: =$C12*$D12 -> 0
C13: =_xlfn.XLOOKUP(A13,'LCATs & Rates'!$A$5:$A$44,'LCATs & Rates'!$F$5:$F$44) -> 0 | E13: =$C13*$D13 -> 0
C14: =_xlfn.XLOOKUP(A14,'LCATs & Rates'!$A$5:$A$44,'LCATs & Rates'!$F$5:$F$44) -> 0 | E14: =$C14*$D14 -> 0
A15: Price per Team per Iteration | E15: =SUM(E3:E14) -> 0
A16: # of Teams Proposed | E16: 1
A17: # of Sprints Proposed | E17: 26
A18: Base Period Subtotal | E18: =E15*E16*E17 -> 0
A20: Other Direct Costs (ODC) / Travel
A21: Item Description | B21: Item Category | C21: Qty | D21: Unit | E21: Cost per Unit | F21: Extended Cost
A22: TBD | B22: Travel | C22: 1 | D22: Lot | E22: 0 | F22: =E22*C22 -> 0
A23: TBD | B23: ODC | C23: 1 | D23: Lot | E23: 0 | F23: =E23*C23 -> 0
E24: ODC/Travel Total | F24: =SUM(F22:F23) -> 0
A27: Labor - OPTION PERIOD 1
A28: Labor Category (Select from List) | B28: Crosswalked Role (Manual entry, if applicable) | C28: Rate per Hour (Calculated) | D28: Hrs per Iteration (Manual Entry) | E28: Option Period
C29: =_xlfn.XLOOKUP(A29,'LCATs & Rates'!$A$5:$A$44,'LCATs & Rates'!$G$5:$G$44) -> 0 | E29: =$C29*$D29 -> 0
C30: =_xlfn.XLOOKUP(A30,'LCATs & Rates'!$A$5:$A$44,'LCATs & Rates'!$G$5:$G$44) -> 0 | E30: =$C30*$D30 -> 0
C31: =_xlfn.XLOOKUP(A31,'LCATs & Rates'!$A$5:$A$44,'LCATs & Rates'!$G$5:$G$44) -> 0 | E31: =$C31*$D31 -> 0
C32: =_xlfn.XLOOKUP(A32,'LCATs & Rates'!$A$5:$A$44,'LCATs & Rates'!$G$5:$G$44) -> 0 | E32: =$C32*$D32 -> 0
C33: =_xlfn.XLOOKUP(A33,'LCATs & Rates'!$A$5:$A$44,'LCATs & Rates'!$G$5:$G$44) -> 0 | E33: =$C33*$D33 -> 0
C34: =_xlfn.XLOOKUP(A34,'LCATs & Rates'!$A$5:$A$44,'LCATs & Rates'!$G$5:$G$44) -> 0 | E34: =$C34*$D34 -> 0
C35: =_xlfn.XLOOKUP(A35,'LCATs & Rates'!$A$5:$A$44,'LCATs & Rates'!$G$5:$G$44) -> 0 | E35: =$C35*$D35 -> 0
C36: =_xlfn.XLOOKUP(A36,'LCATs & Rates'!$A$5:$A$44,'LCATs & Rates'!$G$5:$G$44) -> 0 | E36: =$C36*$D36 -> 0
C37: =_xlfn.XLOOKUP(A37,'LCATs & Rates'!$A$5:$A$44,'LCATs & Rates'!$G$5:$G$44) -> 0 | E37: =$C37*$D37 -> 0
C38: =_xlfn.XLOOKUP(A38,'LCATs & Rates'!$A$5:$A$44,'LCATs & Rates'!$G$5:$G$44) -> 0 | E38: =$C38*$D38 -> 0
C39: =_xlfn.XLOOKUP(A39,'LCATs & Rates'!$A$5:$A$44,'LCATs & Rates'!$G$5:$G$44) -> 0 | E39: =$C39*$D39 -> 0
C40: =_xlfn.XLOOKUP(A40,'LCATs & Rates'!$A$5:$A$44,'LCATs & Rates'!$G$5:$G$44) -> 0 | E40: =$C40*$D40 -> 0
A41: Price per Team per Iteration | E41: =SUM(E29:E40) -> 0
A42: # of Teams Proposed | E42: 1
A43: # of Sprints Proposed | E43: 26
...

Sheet BASE & OPTION_DevOps
A1: Labor - BASE PERIOD
A2: Labor Category (Select from List) | B2: Crosswalked Role (Manual entry, if applicable) | C2: Rate per Hour (Calculated) | D2: Hrs per Iteration (Manual Entry) | E2: Base Period Price per Iteration (Calculated)
C3: =_xlfn.XLOOKUP(A3,'LCATs & Rates'!$A$5:$A$44,'LCATs & Rates'!$F$5:$F$44) -> 0 | E3: =$C3*$D3 -> 0
C4: =_xlfn.XLOOKUP(A4,'LCATs & Rates'!$A$5:$A$44,'LCATs & Rates'!$F$5:$F$44) -> 0 | E4: =$C4*$D4 -> 0
C5: =_xlfn.XLOOKUP(A5,'LCATs & Rates'!$A$5:$A$44,'LCATs & Rates'!$F$5:$F$44) -> 0 | E5: =$C5*$D5 -> 0
C6: =_xlfn.XLOOKUP(A6,'LCATs & Rates'!$A$5:$A$44,'LCATs & Rates'!$F$5:$F$44) -> 0 | E6: =$C6*$D6 -> 0
C7: =_xlfn.XLOOKUP(A7,'LCATs & Rates'!$A$5:$A$44,'LCATs & Rates'!$F$5:$F$44) -> 0 | E7: =$C7*$D7 -> 0
C8: =_xlfn.XLOOKUP(A8,'LCATs & Rates'!$A$5:$A$44,'LCATs & Rates'!$F$5:$F$44) -> 0 | E8: =$C8*$D8 -> 0
C9: =_xlfn.XLOOKUP(A9,'LCATs & Rates'!$A$5:$A$44,'LCATs & Rates'!$F$5:$F$44) -> 0 | E9: =$C9*$D9 -> 0
C10: =_xlfn.XLOOKUP(A10,'LCATs & Rates'!$A$5:$A$44,'LCATs & Rates'!$F$5:$F$44) -> 0 | E10: =$C10*$D10 -> 0
C11: =_xlfn.XLOOKUP(A11,'LCATs & Rates'!$A$5:$A$44,'LCATs & Rates'!$F$5:$F$44) -> 0 | E11: =$C11*$D11 -> 0
C12: =_xlfn.XLOOKUP(A12,'LCATs & Rates'!$A$5:$A$44,'LCATs & Rates'!$F$5:$F$44) -> 0 | E12: =$C12*$D12 -> 0
C13: =_xlfn.XLOOKUP(A13,'LCATs & Rates'!$A$5:$A$44,'LCATs & Rates'!$F$5:$F$44) -> 0 | E13: =$C13*$D13 -> 0
C14: =_xlfn.XLOOKUP(A14,'LCATs & Rates'!$A$5:$A$44,'LCATs & Rates'!$F$5:$F$44) -> 0 | E14: =$C14*$D14 -> 0
A15: Price per Team per Iteration | E15: =SUM(E3:E14) -> 0
A16: # of Teams Proposed | E16: 1
A17: # of Sprints Proposed | E17: 26
A18: Base Period Subtotal | E18: =E15*E16*E17 -> 0
A20: Other Direct Costs (ODC) / Travel
A21: Item Description | B21: Item Category | C21: Qty | D21: Unit | E21: Cost per Unit | F21: Extended Cost
A22: TBD | B22: Travel | C22: 1 | D22: Lot | E22: 0 | F22: =E22*C22 -> 0
A23: TBD | B23: ODC | C23: 1 | D23: Lot | E23: 0 | F23: =E23*C23 -> 0
E24: ODC/Travel Total | F24: =SUM(F22:F23) -> 0
A26: Labor - OPTION PERIOD 1
A27: Labor Category (Select from List) | B27: Crosswalked Role (Manual entry, if applicable) | C27: Rate per Hour (Calculated) | D27: Hrs per Iteration (Manual Entry) | E27: Option Period 1 Price per Iteration (Calculated)
C28: =_xlfn.XLOOKUP(A28,'LCATs & Rates'!$A$5:$A$44,'LCATs & Rates'!$G$5:$G$44) -> 0 | E28: =$C28*$D28 -> 0
C29: =_xlfn.XLOOKUP(A29,'LCATs & Rates'!$A$5:$A$44,'LCATs & Rates'!$G$5:$G$44) -> 0 | E29: =$C29*$D29 -> 0
C30: =_xlfn.XLOOKUP(A30,'LCATs & Rates'!$A$5:$A$44,'LCATs & Rates'!$G$5:$G$44) -> 0 | E30: =$C30*$D30 -> 0
C31: =_xlfn.XLOOKUP(A31,'LCATs & Rates'!$A$5:$A$44,'LCATs & Rates'!$G$5:$G$44) -> 0 | E31: =$C31*$D31 -> 0
C32: =_xlfn.XLOOKUP(A32,'LCATs & Rates'!$A$5:$A$44,'LCATs & Rates'!$G$5:$G$44) -> 0 | E32: =$C32*$D32 -> 0
C33: =_xlfn.XLOOKUP(A33,'LCATs & Rates'!$A$5:$A$44,'LCATs & Rates'!$G$5:$G$44) -> 0 | E33: =$C33*$D33 -> 0
C34: =_xlfn.XLOOKUP(A34,'LCATs & Rates'!$A$5:$A$44,'LCATs & Rates'!$G$5:$G$44) -> 0 | E34: =$C34*$D34 -> 0
C35: =_xlfn.XLOOKUP(A35,'LCATs & Rates'!$A$5:$A$44,'LCATs & Rates'!$G$5:$G$44) -> 0 | E35: =$C35*$D35 -> 0
C36: =_xlfn.XLOOKUP(A36,'LCATs & Rates'!$A$5:$A$44,'LCATs & Rates'!$G$5:$G$44) -> 0 | E36: =$C36*$D36 -> 0
C37: =_xlfn.XLOOKUP(A37,'LCATs & Rates'!$A$5:$A$44,'LCATs & Rates'!$G$5:$G$44) -> 0 | E37: =$C37*$D37 -> 0
C38: =_xlfn.XLOOKUP(A38,'LCATs & Rates'!$A$5:$A$44,'LCATs & Rates'!$G$5:$G$44) -> 0 | E38: =$C38*$D38 -> 0
C39: =_xlfn.XLOOKUP(A39,'LCATs & Rates'!$A$5:$A$44,'LCATs & Rates'!$G$5:$G$44) -> 0 | E39: =$C39*$D39 -> 0
C40: =_xlfn.XLOOKUP(A40,'LCATs & Rates'!$A$5:$A$44,'LCATs & Rates'!$G$5:$G$44) -> 0 | E40: =$C40*$D40 -> 0
A41: Price per Team per Iteration | E41: =SUM(E28:E40) -> 0
A42: # of Teams Proposed | E42: 1
...

Sheet BASE & OPTION_On Call Support
A1: Labor - BASE PERIOD
A2: Labor Category (Select from List) | B2: Crosswalked Role (Manual entry, if applicable) | C2: Rate per Hour (Calculated) | D2: Hrs Not-to-Exceed (Manual Entry) | E2: Base Period Price Not-to-Exceed (Calculated)
A3: Developer | B3: Backend Engineer | C3: =_xlfn.XLOOKUP(A3,'LCATs & Rates'!$A$5:$A$44,'LCATs & Rates'!$F$5:$F$44) -> 186.56 | D3: 144 | E3: =$C3*$D3 -> 26864.64
A4: Developer | B4: Frontend Engineer | C4: =_xlfn.XLOOKUP(A4,'LCATs & Rates'!$A$5:$A$44,'LCATs & Rates'!$F$5:$F$44) -> 186.56 | D4: 72 | E4: =$C4*$D4 -> 13432.32
A5: Developer | B5: DevOps Engineer | C5: =_xlfn.XLOOKUP(A5,'LCATs & Rates'!$A$5:$A$44,'LCATs & Rates'!$F$5:$F$44) -> 186.56 | D5: 144 | E5: =$C5*$D5 -> 26864.64
A6: Developer | B6: QA Engineer | C6: =_xlfn.XLOOKUP(A6,'LCATs & Rates'!$A$5:$A$44,'LCATs & Rates'!$F$5:$F$44) -> 186.56 | D6: 72 | E6: =$C6*$D6 -> 13432.32
C7: =_xlfn.XLOOKUP(A7,'LCATs & Rates'!$A$5:$A$44,'LCATs & Rates'!$F$5:$F$44) -> 0 | E7: =$C7*$D7 -> 0
C8: =_xlfn.XLOOKUP(A8,'LCATs & Rates'!$A$5:$A$44,'LCATs & Rates'!$F$5:$F$44) -> 0 | E8: =$C8*$D8 -> 0
C9: =_xlfn.XLOOKUP(A9,'LCATs & Rates'!$A$5:$A$44,'LCATs & Rates'!$F$5:$F$44) -> 0 | E9: =$C9*$D9 -> 0
C10: =_xlfn.XLOOKUP(A10,'LCATs & Rates'!$A$5:$A$44,'LCATs & Rates'!$F$5:$F$44) -> 0 | E10: =$C10*$D10 -> 0
C11: =_xlfn.XLOOKUP(A11,'LCATs & Rates'!$A$5:$A$44,'LCATs & Rates'!$F$5:$F$44) -> 0 | E11: =$C11*$D11 -> 0
C12: =_xlfn.XLOOKUP(A12,'LCATs & Rates'!$A$5:$A$44,'LCATs & Rates'!$F$5:$F$44) -> 0 | E12: =$C12*$D12 -> 0
C13: =_xlfn.XLOOKUP(A13,'LCATs & Rates'!$A$5:$A$44,'LCATs & Rates'!$F$5:$F$44) -> 0 | E13: =$C13*$D13 -> 0
C14: =_xlfn.XLOOKUP(A14,'LCATs & Rates'!$A$5:$A$44,'LCATs & Rates'!$F$5:$F$44) -> 0 | E14: =$C14*$D14 -> 0
A15: Price Not-to-Exceed | E15: =SUM(E3:E14) -> 80593.92
A17: Labor - OPTION PERIOD 1
A18: Labor Category (Select from List) | B18: Crosswalked Role (Manual entry, if applicable) | C18: Rate per Hour (Calculated) | D18: Hrs Not-to-Exceed (Manual Entry) | E18: Option Period 1 Price Not-to-Exceed (Calculated)
A19: Developer | B19: Backend Engineer | C19: =_xlfn.XLOOKUP(A19,'LCATs & Rates'!$A$5:$A$44,'LCATs & Rates'!$G$5:$G$44) -> 190.2912 | D19: 180 | E19: =$C19*$D19 -> 34252.416
A20: Developer | B20: Frontend Engineer | C20: =_xlfn.XLOOKUP(A20,'LCATs & Rates'!$A$5:$A$44,'LCATs & Rates'!$G$5:$G$44) -> 190.2912 | D20: 90 | E20: =$C20*$D20 -> 17126.208
A21: Developer | B21: DevOps Engineer | C21: =_xlfn.XLOOKUP(A21,'LCATs & Rates'!$A$5:$A$44,'LCATs & Rates'!$G$5:$G$44) -> 190.2912 | D21: 180 | E21: =$C21*$D21 -> 34252.416
A22: Developer | B22: QA Engineer | C22: =_xlfn.XLOOKUP(A22,'LCATs & Rates'!$A$5:$A$44,'LCATs & Rates'!$G$5:$G$44) -> 190.2912 | D22: 90 | E22: =$C22*$D22 -> 17126.208
C23: =_xlfn.XLOOKUP(A23,'LCATs & Rates'!$A$5:$A$44,'LCATs & Rates'!$G$5:$G$44) -> 0 | E23: =$C23*$D23 -> 0
C24: =_xlfn.XLOOKUP(A24,'LCATs & Rates'!$A$5:$A$44,'LCATs & Rates'!$G$5:$G$44) -> 0 | E24: =$C24*$D24 -> 0
C25: =_xlfn.XLOOKUP(A25,'LCATs & Rates'!$A$5:$A$44,'LCATs & Rates'!$G$5:$G$44) -> 0 | E25: =$C25*$D25 -> 0
C26: =_xlfn.XLOOKUP(A26,'LCATs & Rates'!$A$5:$A$44,'LCATs & Rates'!$G$5:$G$44) -> 0 | E26: =$C26*$D26 -> 0
C27: =_xlfn.XLOOKUP(A27,'LCATs & Rates'!$A$5:$A$44,'LCATs & Rates'!$G$5:$G$44) -> 0 | E27: =$C27*$D27 -> 0
C28: =_xlfn.XLOOKUP(A28,'LCATs & Rates'!$A$5:$A$44,'LCATs & Rates'!$G$5:$G$44) -> 0 | E28: =$C28*$D28 -> 0
C29: =_xlfn.XLOOKUP(A29,'LCATs & Rates'!$A$5:$A$44,'LCATs & Rates'!$G$5:$G$44) -> 0 | E29: =$C29*$D29 -> 0
C30: =_xlfn.XLOOKUP(A30,'LCATs & Rates'!$A$5:$A$44,'LCATs & Rates'!$G$5:$G$44) -> 0 | E30: =$C30*$D30 -> 0
A31: Price Not-to-Exceed | E31: =SUM(E19:E30) -> 102757.25
A33: Labor - OPTION PERIOD 2
A34: Labor Category (Select from List) | B34: Crosswalked Role (Manual entry, if applicable) | C34: Rate per Hour (Calculated) | D34: Hrs Not-to-Exceed (Manual Entry) | E34: Option Period 2 Price Not-to-Exceed (Calculated)
A35: Developer | B35: Backend Engineer | C35: =_xlfn.XLOOKUP(A35,'LCATs & Rates'!$A$5:$A$44,'LCATs & Rates'!$G$5:$G$44) -> 190.2912 | D35: 160 | E35: =$C35*$D35 -> 30446.592
A36: Developer | B36: Frontend Engineer | C36: =_xlfn.XLOOKUP(A36,'LCATs & Rates'!$A$5:$A$44,'LCATs & Rates'!$G$5:$G$44) -> 190.2912 | D36: 80 | E36: =$C36*$D36 -> 15223.296
A37: Developer | B37: DevOps Engineer | C37: =_xlfn.XLOOKUP(A37,'LCATs & Rates'!$A$5:$A$44,'LCATs & Rates'!$G$5:$G$44) -> 190.2912 | D37: 160 | E37: =$C37*$D37 -> 30446.592
A38: Developer | B38: QA Engineer | C38: =_xlfn.XLOOKUP(A38,'LCATs & Rates'!$A$5:$A$44,'LCATs & Rates'!$G$5:$G$44) -> 190.2912 | D38: 80 | E38: =$C38*$D38 -> 15223.296
C39: =_xlfn.XLOOKUP(A39,'LCATs & Rates'!$A$5:$A$44,'LCATs & Rates'!$G$5:$G$44) -> 0 | E39: =$C39*$D39 -> 0
C40: =_xlfn.XLOOKUP(A40,'LCATs & Rates'!$A$5:$A$44,'LCATs & Rates'!$G$5:$G$44) -> 0 | E40: =$C40*$D40 -> 0
C41: =_xlfn.XLOOKUP(A41,'LCATs & Rates'!$A$5:$A$44,'LCATs & Rates'!$G$5:$G$44) -> 0 | E41: =$C41*$D41 -> 0
C42: =_xlfn.XLOOKUP(A42,'LCATs & Rates'!$A$5:$A$44,'LCATs & Rates'!$G$5:$G$44) -> 0 | E42: =$C42*$D42 -> 0
...

Sheet 5a_Project Manager
A1: Labor - BASE PERIOD
A2: Labor Category (Select from List) | B2: Crosswalked Role (Manual entry, if applicable) | C2: Rate per Hour (Calculated) | D2: Hrs per Iteration (Manual Entry) | E2: Base Period Price per Iteration (Calculated)
C3: =_xlfn.XLOOKUP(A3,'LCATs & Rates'!$A$5:$A$44,'LCATs & Rates'!$F$5:$F$44) -> 0 | E3: =$C3*$D3 -> 0
C4: =_xlfn.XLOOKUP(A4,'LCATs & Rates'!$A$5:$A$44,'LCATs & Rates'!$F$5:$F$44) -> 0 | E4: =$C4*$D4 -> 0
C5: =_xlfn.XLOOKUP(A5,'LCATs & Rates'!$A$5:$A$44,'LCATs & Rates'!$F$5:$F$44) -> 0 | E5: =$C5*$D5 -> 0
C6: =_xlfn.XLOOKUP(A6,'LCATs & Rates'!$A$5:$A$44,'LCATs & Rates'!$F$5:$F$44) -> 0 | E6: =$C6*$D6 -> 0
C7: =_xlfn.XLOOKUP(A7,'LCATs & Rates'!$A$5:$A$44,'LCATs & Rates'!$F$5:$F$44) -> 0 | E7: =$C7*$D7 -> 0
C8: =_xlfn.XLOOKUP(A8,'LCATs & Rates'!$A$5:$A$44,'LCATs & Rates'!$F$5:$F$44) -> 0 | E8: =$C8*$D8 -> 0
C9: =_xlfn.XLOOKUP(A9,'LCATs & Rates'!$A$5:$A$44,'LCATs & Rates'!$F$5:$F$44) -> 0 | E9: =$C9*$D9 -> 0
C10: =_xlfn.XLOOKUP(A10,'LCATs & Rates'!$A$5:$A$44,'LCATs & Rates'!$F$5:$F$44) -> 0 | E10: =$C10*$D10 -> 0
C11: =_xlfn.XLOOKUP(A11,'LCATs & Rates'!$A$5:$A$44,'LCATs & Rates'!$F$5:$F$44) -> 0 | E11: =$C11*$D11 -> 0
C12: =_xlfn.XLOOKUP(A12,'LCATs & Rates'!$A$5:$A$44,'LCATs & Rates'!$F$5:$F$44) -> 0 | E12: =$C12*$D12 -> 0
C13: =_xlfn.XLOOKUP(A13,'LCATs & Rates'!$A$5:$A$44,'LCATs & Rates'!$F$5:$F$44) -> 0 | E13: =$C13*$D13 -> 0
C14: =_xlfn.XLOOKUP(A14,'LCATs & Rates'!$A$5:$A$44,'LCATs & Rates'!$F$5:$F$44) -> 0 | E14: =$C14*$D14 -> 0
A15: Price per Team per Iteration | E15: =SUM(E3:E14) -> 0
A16: # of Teams | E16: 2
A17: # of Sprints | E17: 26
A18: Base Period Subtotal | E18: =E15*E16*E17 -> 0
A20: Other Direct Costs (ODC) / Travel
A21: Item Description | B21: Item Category | C21: Qty | D21: Unit | E21: Cost per Unit | F21: Extended Cost
A22: TBD | B22: Travel | C22: 1 | D22: Lot | E22: 50000 | F22: =E22*C22 -> 50000
A23: TBD | B23: ODC | C23: 1 | D23: Lot | E23: 10000 | F23: =E23*C23 -> 10000
E24: ODC/Travel Total | F24: =SUM(F22:F23) -> 60000
A27: Labor - OPTION PERIOD 1
A28: Labor Category (Select from List) | B28: Crosswalked Role (Manual entry, if applicable) | C28: Rate per Hour (Calculated) | D28: Hrs per Iteration (Manual Entry) | E28: Option Period
C29: =_xlfn.XLOOKUP(A29,'LCATs & Rates'!$A$5:$A$44,'LCATs & Rates'!$G$5:$G$44) -> 0 | E29: =$C29*$D29 -> 0
C30: =_xlfn.XLOOKUP(A30,'LCATs & Rates'!$A$5:$A$44,'LCATs & Rates'!$G$5:$G$44) -> 0 | E30: =$C30*$D30 -> 0
C31: =_xlfn.XLOOKUP(A31,'LCATs & Rates'!$A$5:$A$44,'LCATs & Rates'!$G$5:$G$44) -> 0 | E31: =$C31*$D31 -> 0
C32: =_xlfn.XLOOKUP(A32,'LCATs & Rates'!$A$5:$A$44,'LCATs & Rates'!$G$5:$G$44) -> 0 | E32: =$C32*$D32 -> 0
C33: =_xlfn.XLOOKUP(A33,'LCATs & Rates'!$A$5:$A$44,'LCATs & Rates'!$G$5:$G$44) -> 0 | E33: =$C33*$D33 -> 0
C34: =_xlfn.XLOOKUP(A34,'LCATs & Rates'!$A$5:$A$44,'LCATs & Rates'!$G$5:$G$44) -> 0 | E34: =$C34*$D34 -> 0
C35: =_xlfn.XLOOKUP(A35,'LCATs & Rates'!$A$5:$A$44,'LCATs & Rates'!$G$5:$G$44) -> 0 | E35: =$C35*$D35 -> 0
C36: =_xlfn.XLOOKUP(A36,'LCATs & Rates'!$A$5:$A$44,'LCATs & Rates'!$G$5:$G$44) -> 0 | E36: =$C36*$D36 -> 0
C37: =_xlfn.XLOOKUP(A37,'LCATs & Rates'!$A$5:$A$44,'LCATs & Rates'!$G$5:$G$44) -> 0 | E37: =$C37*$D37 -> 0
C38: =_xlfn.XLOOKUP(A38,'LCATs & Rates'!$A$5:$A$44,'LCATs & Rates'!$G$5:$G$44) -> 0 | E38: =$C38*$D38 -> 0
C39: =_xlfn.XLOOKUP(A39,'LCATs & Rates'!$A$5:$A$44,'LCATs & Rates'!$G$5:$G$44) -> 0 | E39: =$C39*$D39 -> 0
C40: =_xlfn.XLOOKUP(A40,'LCATs & Rates'!$A$5:$A$44,'LCATs & Rates'!$G$5:$G$44) -> 0 | E40: =$C40*$D40 -> 0
A41: Price per Team per Iteration | E41: =SUM(E29:E40) -> 0
A42: # of Teams Proposed | E42: 2
A43: # of Sprints Proposed | E43: 26
...

Sheet 5b_Product Design
A1: Labor - BASE PERIOD
A2: Labor Category (Select from List) | B2: Crosswalked Role (Manual entry, if applicable) | C2: Rate per Hour (Calculated) | D2: Hrs per Iteration (Manual Entry) | E2: Base Period Price per Iteration (Calculated)
C3: =_xlfn.XLOOKUP(A3,'LCATs & Rates'!$A$5:$A$44,'LCATs & Rates'!$F$5:$F$44) -> 0 | E3: =$C3*$D3 -> 0
C4: =_xlfn.XLOOKUP(A4,'LCATs & Rates'!$A$5:$A$44,'LCATs & Rates'!$F$5:$F$44) -> 0 | E4: =$C4*$D4 -> 0
C5: =_xlfn.XLOOKUP(A5,'LCATs & Rates'!$A$5:$A$44,'LCATs & Rates'!$F$5:$F$44) -> 0 | E5: =$C5*$D5 -> 0
C6: =_xlfn.XLOOKUP(A6,'LCATs & Rates'!$A$5:$A$44,'LCATs & Rates'!$F$5:$F$44) -> 0 | E6: =$C6*$D6 -> 0
C7: =_xlfn.XLOOKUP(A7,'LCATs & Rates'!$A$5:$A$44,'LCATs & Rates'!$F$5:$F$44) -> 0 | E7: =$C7*$D7 -> 0
C8: =_xlfn.XLOOKUP(A8,'LCATs & Rates'!$A$5:$A$44,'LCATs & Rates'!$F$5:$F$44) -> 0 | E8: =$C8*$D8 -> 0
C9: =_xlfn.XLOOKUP(A9,'LCATs & Rates'!$A$5:$A$44,'LCATs & Rates'!$F$5:$F$44) -> 0 | E9: =$C9*$D9 -> 0
C10: =_xlfn.XLOOKUP(A10,'LCATs & Rates'!$A$5:$A$44,'LCATs & Rates'!$F$5:$F$44) -> 0 | E10: =$C10*$D10 -> 0
C11: =_xlfn.XLOOKUP(A11,'LCATs & Rates'!$A$5:$A$44,'LCATs & Rates'!$F$5:$F$44) -> 0 | E11: =$C11*$D11 -> 0
C12: =_xlfn.XLOOKUP(A12,'LCATs & Rates'!$A$5:$A$44,'LCATs & Rates'!$F$5:$F$44) -> 0 | E12: =$C12*$D12 -> 0
C13: =_xlfn.XLOOKUP(A13,'LCATs & Rates'!$A$5:$A$44,'LCATs & Rates'!$F$5:$F$44) -> 0 | E13: =$C13*$D13 -> 0
C14: =_xlfn.XLOOKUP(A14,'LCATs & Rates'!$A$5:$A$44,'LCATs & Rates'!$F$5:$F$44) -> 0 | E14: =$C14*$D14 -> 0
A15: Price per Team per Iteration | E15: =SUM(E3:E14) -> 0
A16: # of Teams Proposed | E16: 2
A17: # of Sprints Proposed | E17: 26
A18: Base Period Subtotal | E18: =E15*E16*E17 -> 0
A20: Other Direct Costs (ODC) / Travel
A21: Item Description | B21: Item Category | C21: Qty | D21: Unit | E21: Cost per Unit | F21: Extended Cost
A22: TBD | B22: Travel | C22: 1 | D22: Lot | E22: 0 | F22: =E22*C22 -> 0
A23: TBD | B23: ODC | C23: 1 | D23: Lot | E23: 0 | F23: =E23*C23 -> 0
E24: ODC/Travel Total | F24: =SUM(F22:F23) -> 0
A27: Labor - OPTION PERIOD 1
A28: Labor Category (Select from List) | B28: Crosswalked Role (Manual entry, if applicable) | C28: Rate per Hour (Calculated) | D28: Hrs per Iteration (Manual Entry) | E28: Option Period
C29: =_xlfn.XLOOKUP(A29,'LCATs & Rates'!$A$5:$A$44,'LCATs & Rates'!$G$5:$G$44) -> 0 | E29: =$C29*$D29 -> 0
C30: =_xlfn.XLOOKUP(A30,'LCATs & Rates'!$A$5:$A$44,'LCATs & Rates'!$G$5:$G$44) -> 0 | E30: =$C30*$D30 -> 0
C31: =_xlfn.XLOOKUP(A31,'LCATs & Rates'!$A$5:$A$44,'LCATs & Rates'!$G$5:$G$44) -> 0 | E31: =$C31*$D31 -> 0
C32: =_xlfn.XLOOKUP(A32,'LCATs & Rates'!$A$5:$A$44,'LCATs & Rates'!$G$5:$G$44) -> 0 | E32: =$C32*$D32 -> 0
C33: =_xlfn.XLOOKUP(A33,'LCATs & Rates'!$A$5:$A$44,'LCATs & Rates'!$G$5:$G$44) -> 0 | E33: =$C33*$D33 -> 0
C34: =_xlfn.XLOOKUP(A34,'LCATs & Rates'!$A$5:$A$44,'LCATs & Rates'!$G$5:$G$44) -> 0 | E34: =$C34*$D34 -> 0
C35: =_xlfn.XLOOKUP(A35,'LCATs & Rates'!$A$5:$A$44,'LCATs & Rates'!$G$5:$G$44) -> 0 | E35: =$C35*$D35 -> 0
C36: =_xlfn.XLOOKUP(A36,'LCATs & Rates'!$A$5:$A$44,'LCATs & Rates'!$G$5:$G$44) -> 0 | E36: =$C36*$D36 -> 0
C37: =_xlfn.XLOOKUP(A37,'LCATs & Rates'!$A$5:$A$44,'LCATs & Rates'!$G$5:$G$44) -> 0 | E37: =$C37*$D37 -> 0
C38: =_xlfn.XLOOKUP(A38,'LCATs & Rates'!$A$5:$A$44,'LCATs & Rates'!$G$5:$G$44) -> 0 | E38: =$C38*$D38 -> 0
C39: =_xlfn.XLOOKUP(A39,'LCATs & Rates'!$A$5:$A$44,'LCATs & Rates'!$G$5:$G$44) -> 0 | E39: =$C39*$D39 -> 0
C40: =_xlfn.XLOOKUP(A40,'LCATs & Rates'!$A$5:$A$44,'LCATs & Rates'!$G$5:$G$44) -> 0 | E40: =$C40*$D40 -> 0
A41: Price per Team per Iteration | E41: =SUM(E29:E40) -> 0
A42: # of Teams Proposed | E42: 2
A43: # of Sprints Proposed | E43: 26
...

Sheet 5c_Engineering
A1: Labor - BASE PERIOD
A2: Labor Category (Select from List) | B2: Crosswalked Role (Manual entry, if applicable) | C2: Rate per Hour (Calculated) | D2: Hrs per Iteration (Manual Entry) | E2: Base Period Price per Iteration (Calculated)
C3: =_xlfn.XLOOKUP(A3,'LCATs & Rates'!$A$5:$A$44,'LCATs & Rates'!$F$5:$F$44) -> 0 | E3: =$C3*$D3 -> 0
C4: =_xlfn.XLOOKUP(A4,'LCATs & Rates'!$A$5:$A$44,'LCATs & Rates'!$F$5:$F$44) -> 0 | E4: =$C4*$D4 -> 0
C5: =_xlfn.XLOOKUP(A5,'LCATs & Rates'!$A$5:$A$44,'LCATs & Rates'!$F$5:$F$44) -> 0 | E5: =$C5*$D5 -> 0
C6: =_xlfn.XLOOKUP(A6,'LCATs & Rates'!$A$5:$A$44,'LCATs & Rates'!$F$5:$F$44) -> 0 | E6: =$C6*$D6 -> 0
C7: =_xlfn.XLOOKUP(A7,'LCATs & Rates'!$A$5:$A$44,'LCATs & Rates'!$F$5:$F$44) -> 0 | E7: =$C7*$D7 -> 0
C8: =_xlfn.XLOOKUP(A8,'LCATs & Rates'!$A$5:$A$44,'LCATs & Rates'!$F$5:$F$44) -> 0 | E8: =$C8*$D8 -> 0
C9: =_xlfn.XLOOKUP(A9,'LCATs & Rates'!$A$5:$A$44,'LCATs & Rates'!$F$5:$F$44) -> 0 | E9: =$C9*$D9 -> 0
C10: =_xlfn.XLOOKUP(A10,'LCATs & Rates'!$A$5:$A$44,'LCATs & Rates'!$F$5:$F$44) -> 0 | E10: =$C10*$D10 -> 0
C11: =_xlfn.XLOOKUP(A11,'LCATs & Rates'!$A$5:$A$44,'LCATs & Rates'!$F$5:$F$44) -> 0 | E11: =$C11*$D11 -> 0
C12: =_xlfn.XLOOKUP(A12,'LCATs & Rates'!$A$5:$A$44,'LCATs & Rates'!$F$5:$F$44) -> 0 | E12: =$C12*$D12 -> 0
C13: =_xlfn.XLOOKUP(A13,'LCATs & Rates'!$A$5:$A$44,'LCATs & Rates'!$F$5:$F$44) -> 0 | E13: =$C13*$D13 -> 0
C14: =_xlfn.XLOOKUP(A14,'LCATs & Rates'!$A$5:$A$44,'LCATs & Rates'!$F$5:$F$44) -> 0 | E14: =$C14*$D14 -> 0
A15: Price per Team per Iteration | E15: =SUM(E3:E14) -> 0
A16: # of Teams Proposed | E16: 2
A17: # of Sprints Proposed | E17: 26
A18: Base Period Subtotal | E18: =E15*E16*E17 -> 0
A20: Other Direct Costs (ODC) / Travel
A21: Item Description | B21: Item Category | C21: Qty | D21: Unit | E21: Cost per Unit | F21: Extended Cost
A22: TBD | B22: Travel | C22: 1 | D22: Lot | E22: 0 | F22: =E22*C22 -> 0
A23: TBD | B23: ODC | C23: 1 | D23: Lot | E23: 0 | F23: =E23*C23 -> 0
E24: ODC/Travel Total | F24: =SUM(F22:F23) -> 0
A27: Labor - OPTION PERIOD 1
A28: Labor Category (Select from List) | B28: Crosswalked Role (Manual entry, if applicable) | C28: Rate per Hour (Calculated) | D28: Hrs per Iteration (Manual Entry) | E28: Option Period
C29: =_xlfn.XLOOKUP(A29,'LCATs & Rates'!$A$5:$A$44,'LCATs & Rates'!$G$5:$G$44) -> 0 | E29: =$C29*$D29 -> 0
C30: =_xlfn.XLOOKUP(A30,'LCATs & Rates'!$A$5:$A$44,'LCATs & Rates'!$G$5:$G$44) -> 0 | E30: =$C30*$D30 -> 0
C31: =_xlfn.XLOOKUP(A31,'LCATs & Rates'!$A$5:$A$44,'LCATs & Rates'!$G$5:$G$44) -> 0 | E31: =$C31*$D31 -> 0
C32: =_xlfn.XLOOKUP(A32,'LCATs & Rates'!$A$5:$A$44,'LCATs & Rates'!$G$5:$G$44) -> 0 | E32: =$C32*$D32 -> 0
C33: =_xlfn.XLOOKUP(A33,'LCATs & Rates'!$A$5:$A$44,'LCATs & Rates'!$G$5:$G$44) -> 0 | E33: =$C33*$D33 -> 0
C34: =_xlfn.XLOOKUP(A34,'LCATs & Rates'!$A$5:$A$44,'LCATs & Rates'!$G$5:$G$44) -> 0 | E34: =$C34*$D34 -> 0
C35: =_xlfn.XLOOKUP(A35,'LCATs & Rates'!$A$5:$A$44,'LCATs & Rates'!$G$5:$G$44) -> 0 | E35: =$C35*$D35 -> 0
C36: =_xlfn.XLOOKUP(A36,'LCATs & Rates'!$A$5:$A$44,'LCATs & Rates'!$G$5:$G$44) -> 0 | E36: =$C36*$D36 -> 0
C37: =_xlfn.XLOOKUP(A37,'LCATs & Rates'!$A$5:$A$44,'LCATs & Rates'!$G$5:$G$44) -> 0 | E37: =$C37*$D37 -> 0
C38: =_xlfn.XLOOKUP(A38,'LCATs & Rates'!$A$5:$A$44,'LCATs & Rates'!$G$5:$G$44) -> 0 | E38: =$C38*$D38 -> 0
C39: =_xlfn.XLOOKUP(A39,'LCATs & Rates'!$A$5:$A$44,'LCATs & Rates'!$G$5:$G$44) -> 0 | E39: =$C39*$D39 -> 0
C40: =_xlfn.XLOOKUP(A40,'LCATs & Rates'!$A$5:$A$44,'LCATs & Rates'!$G$5:$G$44) -> 0 | E40: =$C40*$D40 -> 0
A41: Price per Team per Iteration | E41: =SUM(E29:E40) -> 0
A42: # of Teams Proposed | E42: 2
A43: # of Sprints Proposed | E43: 26
...

Sheet 5d_DevOps
A1: Labor - BASE PERIOD
A2: Labor Category (Select from List) | B2: Crosswalked Role (Manual entry, if applicable) | C2: Rate per Hour (Calculated) | D2: Hrs per Iteration (Manual Entry) | E2: Base Period Price per Iteration (Calculated)
C3: =_xlfn.XLOOKUP(A3,'LCATs & Rates'!$A$5:$A$44,'LCATs & Rates'!$F$5:$F$44) -> 0 | E3: =$C3*$D3 -> 0
C4: =_xlfn.XLOOKUP(A4,'LCATs & Rates'!$A$5:$A$44,'LCATs & Rates'!$F$5:$F$44) -> 0 | E4: =$C4*$D4 -> 0
C5: =_xlfn.XLOOKUP(A5,'LCATs & Rates'!$A$5:$A$44,'LCATs & Rates'!$F$5:$F$44) -> 0 | E5: =$C5*$D5 -> 0
C6: =_xlfn.XLOOKUP(A6,'LCATs & Rates'!$A$5:$A$44,'LCATs & Rates'!$F$5:$F$44) -> 0 | E6: =$C6*$D6 -> 0
C7: =_xlfn.XLOOKUP(A7,'LCATs & Rates'!$A$5:$A$44,'LCATs & Rates'!$F$5:$F$44) -> 0 | E7: =$C7*$D7 -> 0
C8: =_xlfn.XLOOKUP(A8,'LCATs & Rates'!$A$5:$A$44,'LCATs & Rates'!$F$5:$F$44) -> 0 | E8: =$C8*$D8 -> 0
C9: =_xlfn.XLOOKUP(A9,'LCATs & Rates'!$A$5:$A$44,'LCATs & Rates'!$F$5:$F$44) -> 0 | E9: =$C9*$D9 -> 0
C10: =_xlfn.XLOOKUP(A10,'LCATs & Rates'!$A$5:$A$44,'LCATs & Rates'!$F$5:$F$44) -> 0 | E10: =$C10*$D10 -> 0
C11: =_xlfn.XLOOKUP(A11,'LCATs & Rates'!$A$5:$A$44,'LCATs & Rates'!$F$5:$F$44) -> 0 | E11: =$C11*$D11 -> 0
C12: =_xlfn.XLOOKUP(A12,'LCATs & Rates'!$A$5:$A$44,'LCATs & Rates'!$F$5:$F$44) -> 0 | E12: =$C12*$D12 -> 0
C13: =_xlfn.XLOOKUP(A13,'LCATs & Rates'!$A$5:$A$44,'LCATs & Rates'!$F$5:$F$44) -> 0 | E13: =$C13*$D13 -> 0
C14: =_xlfn.XLOOKUP(A14,'LCATs & Rates'!$A$5:$A$44,'LCATs & Rates'!$F$5:$F$44) -> 0 | E14: =$C14*$D14 -> 0
A15: Price per Team per Iteration | E15: =SUM(E3:E14) -> 0
A16: # of Teams Proposed | E16: 2
A17: # of Sprints Proposed | E17: 26
A18: Base Period Subtotal | E18: =E15*E16*E17 -> 0
A20: Other Direct Costs (ODC) / Travel
A21: Item Description | B21: Item Category | C21: Qty | D21: Unit | E21: Cost per Unit | F21: Extended Cost
A22: TBD | B22: Travel | C22: 1 | D22: Lot | E22: 0 | F22: =E22*C22 -> 0
A23: TBD | B23: ODC | C23: 1 | D23: Lot | E23: 0 | F23: =E23*C23 -> 0
E24: ODC/Travel Total | F24: =SUM(F22:F23) -> 0
A27: Labor - OPTION PERIOD 1
A28: Labor Category (Select from List) | B28: Crosswalked Role (Manual entry, if applicable) | C28: Rate per Hour (Calculated) | D28: Hrs per Iteration (Manual Entry) | E28: Option Period
C29: =_xlfn.XLOOKUP(A29,'LCATs & Rates'!$A$5:$A$44,'LCATs & Rates'!$G$5:$G$44) -> 0 | E29: =$C29*$D29 -> 0
C30: =_xlfn.XLOOKUP(A30,'LCATs & Rates'!$A$5:$A$44,'LCATs & Rates'!$G$5:$G$44) -> 0 | E30: =$C30*$D30 -> 0
C31: =_xlfn.XLOOKUP(A31,'LCATs & Rates'!$A$5:$A$44,'LCATs & Rates'!$G$5:$G$44) -> 0 | E31: =$C31*$D31 -> 0
C32: =_xlfn.XLOOKUP(A32,'LCATs & Rates'!$A$5:$A$44,'LCATs & Rates'!$G$5:$G$44) -> 0 | E32: =$C32*$D32 -> 0
C33: =_xlfn.XLOOKUP(A33,'LCATs & Rates'!$A$5:$A$44,'LCATs & Rates'!$G$5:$G$44) -> 0 | E33: =$C33*$D33 -> 0
C34: =_xlfn.XLOOKUP(A34,'LCATs & Rates'!$A$5:$A$44,'LCATs & Rates'!$G$5:$G$44) -> 0 | E34: =$C34*$D34 -> 0
C35: =_xlfn.XLOOKUP(A35,'LCATs & Rates'!$A$5:$A$44,'LCATs & Rates'!$G$5:$G$44) -> 0 | E35: =$C35*$D35 -> 0
C36: =_xlfn.XLOOKUP(A36,'LCATs & Rates'!$A$5:$A$44,'LCATs & Rates'!$G$5:$G$44) -> 0 | E36: =$C36*$D36 -> 0
C37: =_xlfn.XLOOKUP(A37,'LCATs & Rates'!$A$5:$A$44,'LCATs & Rates'!$G$5:$G$44) -> 0 | E37: =$C37*$D37 -> 0
C38: =_xlfn.XLOOKUP(A38,'LCATs & Rates'!$A$5:$A$44,'LCATs & Rates'!$G$5:$G$44) -> 0 | E38: =$C38*$D38 -> 0
C39: =_xlfn.XLOOKUP(A39,'LCATs & Rates'!$A$5:$A$44,'LCATs & Rates'!$G$5:$G$44) -> 0 | E39: =$C39*$D39 -> 0
C40: =_xlfn.XLOOKUP(A40,'LCATs & Rates'!$A$5:$A$44,'LCATs & Rates'!$G$5:$G$44) -> 0 | E40: =$C40*$D40 -> 0
A41: Price per Team per Iteration | E41: =SUM(E29:E40) -> 0
A42: # of Teams Proposed | E42: 2
A43: # of Sprints Proposed | E43: 26
...
